Workbook

Sheet Data Sheet
A1: COMPANY NAME | B1: BHARAT HEAVY ELECTRICALS LTD | E1: =IF(B2<>B3, "A NEW VERSION OF THE WORKSHEET IS AVAILABLE", "")
A2: LATEST VERSION | B2: 2.1 | E2: PLEASE DO NOT MAKE ANY CHANGES TO THIS SHEET
A3: CURRENT VERSION | B3: 2.1
A5: META
A6: Number of shares | B6: =IF(B9>0, B9/B8, 0)
A7: Face Value | B7: 2
A8: Current Price | B8: 402.7
A9: Market Capitalization | B9: 140222.69
A15: PROFIT & LOSS
A16: Report Date | B16: 42825 | C16: 43190 | D16: 43555 | E16: 43921 | F16: 44286 | G16: 44651 | H16: 45016 | I16: 45382 | J16: 45747 | K16: 46112
A17: Sales | B17: 28464.77 | C17: 28827.48 | D17: 30441.38 | E17: 21463.14 | F17: 17308.69 | G17: 21211.09 | H17: 23364.94 | I17: 23892.78 | J17: 28339.48 | K17: 33782.18
A18: Raw Material Cost | B18: 13125.88 | C18: 12102.78 | D18: 14982.73 | E18: 11781.64 | F18: 8158.56 | G18: 9204.15 | H18: 10532.61 | I18: 11984.73 | J18: 14965.64 | K18: 24274.28
A19: Change in Inventory | B19: -992.94 | C19: -739 | D19: 989.31 | E19: -1042.43 | F19: 510.86 | G19: 525.64 | H19: -57.15 | I19: -436.74 | J19: -1542.32 | K19: -1291.19
A20: Power and Fuel | B20: 451.55 | C20: 463.62 | D20: 496.94 | E20: 459.41 | F20: 319.57 | G20: 415.08 | H20: 487.67 | I20: 452.2 | J20: 490.64
A21: Other Mfr. Exp | B21: 3740.25 | C21: 4329.32 | D21: 4560.74 | E21: 3522.22 | F21: 3384.61 | G21: 5229.76 | H21: 6008.66 | I21: 5472.07 | J21: 5685.56
A22: Employee Cost | B22: 5402.71 | C22: 6075.55 | D22: 5509.25 | E22: 5431.88 | F22: 5378.36 | G22: 5519.05 | H22: 5700.63 | I22: 5628.84 | J22: 5923.42 | K22: 6467.62
A23: Selling and admin | B23: 1448.06 | C23: 1365.75 | D23: 1795.59 | E23: 1542.87 | F23: 1136.43 | G23: 1047.14 | H23: 1142.85 | I23: 1145.12 | J23: 1311.68
A24: Other Expenses | B24: 2208.37 | C24: 2098.33 | D24: 2053.19 | E24: -99.3 | F24: 1468.98 | G24: -1557.77 | H24: -1493.98 | I24: -1064.33 | J24: 105.54 | K24: 1989.28
A25: Other Income | B25: 753.19 | C25: 679.24 | D25: 661.52 | E25: 590.02 | F25: 392.56 | G25: 404.67 | H25: 544.49 | I25: 608.31 | J25: 524.32 | K25: 868.7
A26: Depreciation | B26: 849.79 | C26: 787.33 | D26: 475.74 | E26: 503.27 | F26: 473.25 | G26: 314.12 | H26: 260.34 | I26: 248.9 | J26: 271.96 | K26: 315.87
A27: Interest | B27: 412.84 | C27: 330.17 | D27: 378.29 | E27: 612.67 | F27: 466.56 | G27: 448.13 | H27: 612.19 | I27: 827.64 | J27: 906.08 | K27: 756.41
A28: Profit before tax | B28: 585.57 | C28: 1214.87 | D28: 1839.74 | E28: -659.07 | F28: -3595.93 | G28: 470.46 | H28: 715.61 | I28: 242.66 | J28: 745.6 | K28: 2138.61
A29: Tax | B29: 130.39 | C29: 776.68 | D29: 837.32 | E29: 809.28 | F29: -896.23 | G29: 25.75 | H29: 61.49 | I29: -39.56 | J29: 211.7 | K29: 538.35
A30: Net profit | B30: 457.26 | C30: 441.16 | D30: 1005.1 | E30: -1466.01 | F30: -2697.11 | G30: 446.03 | H30: 654.12 | I30: 282.22 | J30: 533.9 | K30: 1600.26
A31: Dividend Amount | B31: 386.72 | C31: 668.19 | D31: 696.41 | G31: 139.28 | H31: 139.28 | I31: 87.05 | J31: 174.1 | K31: 487.49
E32: 22712.23 | F32: 21297.18 | G32: 21145.59 | H32: 23430.15 | I32: 24260.37 | J32: 28118.2 | K32: 32512.27
E33: =SUM(E18:E24)+E26+E27 | F33: =SUM(F18:F24)+F26+F27 | G33: =SUM(G18:G24)+G26+G27 | H33: =SUM(H18:H24)+H26+H27 | I33: =SUM(I18:I24)+I26+I27 | J33: =SUM(J18:J24)+J26+J27 | K33: =SUM(K18:K24)+K26+K27
E34: =E23+E24 | F34: =F23+F24 | G34: =G23+G24 | H34: =H23+H24 | I34: =I23+I24 | J34: =J23+J24 | K34: =K23+K24
E37: 21596 | F37: 20357 | G37: 20383 | H37: 22321 | I37: 23182 | J37: 26940 | K37: 31440
E38: =E37-E18-E19-E20-E21-E22 | F38: =F37-F18-F19-F20-F21-F22 | G38: =G37-G18-G19-G20-G21-G22 | H38: =H37-H18-H19-H20-H21-H22 | I38: =I37-I18-I19-I20-I21-I22 | J38: =J37-J18-J19-J20-J21-J22 | K38: =K37-K18-K19-K20-K21-K22
A43: Quarters
A44: Report Date | B44: 45291 | C44: 45382 | D44: 45473 | E44: 45565 | F44: 45657 | G44: 45747 | H44: 45838 | I44: 45930 | J44: 46022 | K44: 46112
A45: Sales | B45: 5503.81 | C45: 8260.25 | D45: 5484.92 | E45: 6584.1 | F45: 7277.09 | G45: 8993.37 | H45: 5486.91 | I45: 7511.8 | J45: 8473.1 | K45: 12310.37
A46: Expenses | B46: 5287.26 | C46: 7532.39 | D46: 5654.27 | E46: 6309.1 | F46: 6972.85 | G46: 8161.69 | H46: 6024.05 | I46: 6930.87 | J46: 7927.8 | K46: 10557.27
A47: Other Income | B47: 118.15 | C47: 170.18 | D47: 111.07 | E47: 127.89 | F47: 126.17 | G47: 159.19 | H47: 184.83 | I47: 188.97 | J47: 234.99 | K47: 259.91
A48: Depreciation | B48: 60.6 | C48: 68.4 | D48: 58.97 | E48: 60.09 | F48: 67.88 | G48: 85.02 | H48: 74.52 | I48: 75.46 | J48: 77.99 | K48: 87.9
A49: Interest | B49: 189.6 | C49: 193.32 | D49: 161.74 | E49: 201.38 | F49: 183.78 | G49: 201.43 | H49: 181.21 | I49: 195.21 | J49: 182.47 | K49: 197.52
A50: Profit before tax | B50: 84.5 | C50: 636.32 | D50: -278.99 | E50: 141.42 | F50: 178.75 | G50: 704.42 | H50: -608.04 | I50: 499.23 | J50: 519.83 | K50: 1727.59
A51: Tax | B51: 24.18 | C51: 146.7 | D51: -67.59 | E51: 35.27 | F51: 44.05 | G51: 199.97 | H51: -152.54 | I51: 124.34 | J51: 129.43 | K51: 437.12
A52: Net profit | B52: 60.32 | C52: 489.62 | D52: -211.4 | E52: 106.15 | F52: 134.7 | G52: 504.45 | H52: -455.5 | I52: 374.89 | J52: 390.4 | K52: 1290.47
...

Sheet Sheet1
A1: Indicator | C1: Mar 20 | D1: Mar 21 | E1: Mar 22 | F1: Mar 23 | G1: Mar 24 | H1: Mar 25 | I1: Mar 26 | Y1: Mar 19 | Z1: Mar 18 | AA1: Mar 17 | AB1: Mar 16 | AC1: Mar 15 | AD1: Mar 14 | AE1: Mar 13 | AF1: Mar 12 | AG1: Mar 11 | AH1: Mar 10 | AI1: Mar 09
A2: INCOME
A3: Revenue From Operations [Gross] | C3: 20494.59 | D3: 16295.8 | E3: 20153.38 | F3: 22136.3 | G3: 22920.52 | H3: 27355.17 | I3: 33782.18 | L3: =VALUE(C3) | M3: =VALUE(D3) | N3: =VALUE(E3) | O3: =VALUE(F3) | P3: =VALUE(G3) | Q3: =VALUE(H3) | R3: =VALUE(I3) | Y3: 29,441.59 | Z3: 28,112.82 | AA3: 28,871.89 | AB3: 27,541.19 | AC3: 31,554.76 | AD3: 40,801.99 | AE3: 50,672.84 | AF3: 49,897.57 | AG3: 43,635.73 | AH3: 34,687.55 | AI3: 28,564.81
A4: Less: Excise/Sevice Tax/Other Levies | C4: 0 | D4: 0 | E4: 0 | F4: 0 | G4: 0 | H4: 0 | I4: 0 | L4: =VALUE(C4) | M4: =VALUE(D4) | N4: =VALUE(E4) | O4: =VALUE(F4) | P4: =VALUE(G4) | Q4: =VALUE(H4) | R4: =VALUE(I4) | Y4: 0.00 | Z4: 135.04 | AA4: 1,254.47 | AB4: 1,451.02 | AC4: 1,407.24 | AD4: 1,953.70 | AE4: 2,566.53 | AF4: 2,298.62 | AG4: 1,781.07 | AH4: 1,394.28 | AI4: 1,896.03
A5: Revenue From Operations [Net] | C5: 20494.59 | D5: 16295.8 | E5: 20153.38 | F5: 22136.3 | G5: 22920.52 | H5: 27355.17 | I5: 33782.18 | L5: =VALUE(C5) | M5: =VALUE(D5) | N5: =VALUE(E5) | O5: =VALUE(F5) | P5: =VALUE(G5) | Q5: =VALUE(H5) | R5: =VALUE(I5) | Y5: 29,441.59 | Z5: 27,977.78 | AA5: 27,617.42 | AB5: 26,090.17 | AC5: 30,147.52 | AD5: 38,848.29 | AE5: 48,106.31 | AF5: 47,598.95 | AG5: 41,854.66 | AH5: 33,293.27 | AI5: 26,668.78
A6: Total Operating Revenues | C6: 21463.14 | D6: 17308.69 | E6: 21211.09 | F6: 23364.94 | G6: 23892.78 | H6: 28339.48 | I6: 33782.18 | L6: =VALUE(C6) | M6: =VALUE(D6) | N6: =VALUE(E6) | O6: =VALUE(F6) | P6: =VALUE(G6) | Q6: =VALUE(H6) | R6: =VALUE(I6) | Y6: 30,441.38 | Z6: 28,940.42 | AA6: 28,477.03 | AB6: 26,678.52 | AC6: 30,788.59 | AD6: 39,569.41 | AE6: 48,915.84 | AF6: 48,355.22 | AG6: 42,538.24 | AH6: 33,293.27 | AI6: 26,668.78
A7: Other Income | C7: 564.3 | D7: 348.42 | E7: 354.54 | F7: 488.63 | G7: 546.27 | H7: 465.31 | I7: 807.65 | L7: =VALUE(C7) | M7: =VALUE(D7) | N7: =VALUE(E7) | O7: =VALUE(F7) | P7: =VALUE(G7) | Q7: =VALUE(H7) | R7: =VALUE(I7) | Y7: 661.52 | Z7: 678.01 | AA7: 753.19 | AB7: 1,476.43 | AC7: 1,230.59 | AD7: 1,623.02 | AE7: 1,128.76 | AF7: 1,272.03 | AG7: 1,026.93 | AH7: 1,429.24 | AI7: 1,252.44
A8: Total Revenue | C8: 22027.44 | D8: 17657.11 | E8: 21565.63 | F8: 23853.57 | G8: 24439.05 | H8: 28804.79 | I8: 34589.83 | L8: =VALUE(C8) | M8: =VALUE(D8) | N8: =VALUE(E8) | O8: =VALUE(F8) | P8: =VALUE(G8) | Q8: =VALUE(H8) | R8: =VALUE(I8) | Y8: 31,102.90 | Z8: 29,618.43 | AA8: 29,230.22 | AB8: 28,154.95 | AC8: 32,019.18 | AD8: 41,192.43 | AE8: 50,044.60 | AF8: 49,627.25 | AG8: 43,565.17 | AH8: 34,722.51 | AI8: 27,921.22
A9: EXPENSES
A10: Cost Of Materials Consumed | C10: 12134.55 | D10: 8447.3 | E10: 5327.07 | F10: 6279.46 | G10: 6466.55 | H10: 8640.26 | I10: 24274.28 | L10: =VALUE(C10) | M10: =VALUE(D10) | N10: =VALUE(E10) | O10: =VALUE(F10) | P10: =VALUE(G10) | Q10: =VALUE(H10) | R10: =VALUE(I10) | Y10: 15,394.44 | Z10: 12,488.60 | AA10: 13,535.17 | AB10: 13,428.64 | AC10: 14,674.40 | AD10: 18,032.61 | AE10: 28,171.38 | AF10: 25,266.60 | AG10: 20,016.64 | AH10: 18,256.99 | AI10: 16,091.21
A11: Purchase Of Stock-In Trade | C11: 0 | D11: 0 | E11: 4141.75 | F11: 4657.33 | G11: 5868.46 | H11: 6757.99 | I11: 0 | L11: =VALUE(C11) | M11: =VALUE(D11) | N11: =VALUE(E11) | O11: =VALUE(F11) | P11: =VALUE(G11) | Q11: =VALUE(H11) | R11: =VALUE(I11) | Y11: 0.00 | Z11: 0.00 | AA11: 0.00 | AB11: 0.00 | AC11: 0.00 | AD11: 0.00 | AE11: 0.00 | AF11: 0.00 | AG11: 0.00 | AH11: 0.00 | AI11: 0.00
A12: Operating And Direct Expenses | C12: 2947.17 | D12: 2912.47 | E12: 4792.61 | F12: 5421.08 | G12: 4908.84 | H12: 4989.22 | I12: 0 | L12: =VALUE(C12) | M12: =VALUE(D12) | N12: =VALUE(E12) | O12: =VALUE(F12) | P12: =VALUE(G12) | Q12: =VALUE(H12) | R12: =VALUE(I12) | Y12: 3,866.88 | Z12: 3,418.67 | AA12: 3,055.51 | AB12: 2,978.08 | AC12: 3,604.10 | AD12: 4,428.91 | AE12: 0.00 | AF12: 3,865.84 | AG12: 3,350.01 | AH12: 3,010.67 | AI12: 2,149.53
A13: Changes In Inventories Of FG,WIP And Stock-In Trade | C13: -1042.43 | D13: 510.86 | E13: 532.41 | F13: -57.15 | G13: -436.74 | H13: -1542.32 | I13: -1291.19 | L13: =VALUE(C13) | M13: =VALUE(D13) | N13: =VALUE(E13) | O13: =VALUE(F13) | P13: =VALUE(G13) | Q13: =VALUE(H13) | R13: =VALUE(I13) | Y13: -989.31 | Z13: 739.00 | AA13: 992.94 | AB13: 210.05 | AC13: -339.50 | AD13: 1,057.14 | AE13: 121.20 | AF13: -829.65 | AG13: -126.18 | AH13: -775.80 | AI13: -1,163.99
A14: Employee Benefit Expenses | C14: 5431.88 | D14: 5378.15 | E14: 5519.05 | F14: 5700.63 | G14: 5628.84 | H14: 5923.42 | I14: 6467.62 | L14: =VALUE(C14) | M14: =VALUE(D14) | N14: =VALUE(E14) | O14: =VALUE(F14) | P14: =VALUE(G14) | Q14: =VALUE(H14) | R14: =VALUE(I14) | Y14: 5,509.25 | Z14: 6,034.68 | AA14: 5,402.71 | AB14: 5,387.33 | AC14: 5,475.48 | AD14: 5,956.57 | AE14: 5,824.00 | AF14: 5,529.77 | AG14: 5,452.60 | AH14: 6,499.83 | AI14: 3,027.12
A15: Finance Costs | C15: 508.45 | D15: 373.95 | E15: 355.96 | F15: 521.43 | G15: 731.29 | H15: 748.33 | I15: 756.41 | L15: =VALUE(C15) | M15: =VALUE(D15) | N15: =VALUE(E15) | O15: =VALUE(F15) | P15: =VALUE(G15) | Q15: =VALUE(H15) | R15: =VALUE(I15) | Y15: 288.37 | Z15: 255.16 | AA15: 351.30 | AB15: 359.81 | AC15: 92.43 | AD15: 133.46 | AE15: 127.61 | AF15: 53.07 | AG15: 56.38 | AH15: 36.69 | AI15: 35.18
A16: Depreciation And Amortisation Expenses | C16: 503.27 | D16: 473.25 | E16: 314.12 | F16: 260.34 | G16: 248.9 | H16: 271.96 | I16: 315.87 | L16: =VALUE(C16) | M16: =VALUE(D16) | N16: =VALUE(E16) | O16: =VALUE(F16) | P16: =VALUE(G16) | Q16: =VALUE(H16) | R16: =VALUE(I16) | Y16: 475.74 | Z16: 787.33 | AA16: 849.79 | AB16: 936.70 | AC16: 1,082.01 | AD16: 985.36 | AE16: 957.18 | AF16: 803.24 | AG16: 546.37 | AH16: 460.26 | AI16: 343.07
A17: Other Expenses | C17: 1995.54 | D17: 1733.74 | E17: 1688.87 | F17: 647.03 | G17: 844.23 | H17: 2329.34 | I17: 1989.28 | L17: =VALUE(C17) | M17: =VALUE(D17) | N17: =VALUE(E17) | O17: =VALUE(F17) | P17: =VALUE(G17) | Q17: =VALUE(H17) | R17: =VALUE(I17) | Y17: 2,698.13 | Z17: 2,155.94 | AA17: 3,013.33 | AB17: 4,037.97 | AC17: 3,655.50 | AD17: 3,323.55 | AE17: 3,808.31 | AF17: 3,250.76 | AG17: 2,557.00 | AH17: 612.99 | AI17: 2,608.46
A18: Total Expenses | C18: 22712.23 | D18: 21297.18 | E18: 21145.59 | F18: 23430.15 | G18: 24260.37 | H18: 28118.2 | I18: 32512.27 | L18: =VALUE(C18) | M18: =VALUE(D18) | N18: =VALUE(E18) | O18: =VALUE(F18) | P18: =VALUE(G18) | Q18: =VALUE(H18) | R18: =VALUE(I18) | Y18: 29,077.56 | Z18: 28,012.80 | AA18: 28,621.09 | AB18: 29,331.92 | AC18: 29,821.60 | AD18: 36,108.75 | AE18: 40,517.58 | AF18: 39,241.05 | AG18: 34,505.77 | AH18: 28,101.63 | AI18: 23,090.58
C19: =SUM(C10:C17) | D19: =SUM(D10:D17) | E19: =SUM(E10:E17) | F19: =SUM(F10:F17) | G19: =SUM(G10:G17) | H19: =SUM(H10:H17) | I19: =SUM(I10:I17)
C20: =C18-C19 | D20: =D18-D19 | E20: =E18-E19 | F20: =F18-F19 | G20: =G18-G19 | H20: =H18-H19 | I20: =I18-I19
C21: =C8-C18 | D21: =D8-D18 | E21: =E8-E18 | F21: =F8-F18 | G21: =G8-G18 | H21: =H8-H18 | I21: =I8-I18
A22: Profit/Loss Before Exceptional, ExtraOrdinary Items And Tax | C22: -684.79 | D22: -3640.07 | E22: 420.04 | F22: 423.42 | G22: 178.68 | H22: 686.59 | I22: 2077.56 | L22: =VALUE(C22) | M22: =VALUE(D22) | N22: =VALUE(E22) | O22: =VALUE(F22) | P22: =VALUE(G22) | Q22: =VALUE(H22) | R22: =VALUE(I22) | Y22: 2,025.34 | Z22: 1,605.63 | AA22: 609.13 | AB22: -1,176.97 | AC22: 2,197.58 | AD22: 5,083.68 | AE22: 9,527.02 | AF22: 10,386.20 | AG22: 9,059.40 | AH22: 6,620.88 | AI22: 4,830.64
A23: Exceptional Items | C23: 0 | D23: 0 | E23: 0 | F23: 0 | G23: 0 | H23: 0 | I23: 0 | L23: =VALUE(C23) | M23: =VALUE(D23) | N23: =VALUE(E23) | O23: =VALUE(F23) | P23: =VALUE(G23) | Q23: =VALUE(H23) | R23: =VALUE(I23) | Y23: 0.00 | Z23: 0.00 | AA23: 0.00 | AB23: 0.00 | AC23: 0.00 | AD23: 0.00 | AE23: 4.14 | AF23: 0.16 | AG23: 7.75 | AH23: 0.00 | AI23: 0.00
A24: Profit/Loss Before Tax | C24: -684.79 | D24: -3640.07 | E24: 420.04 | F24: 423.42 | G24: 178.68 | H24: 686.59 | I24: 2077.56 | L24: =VALUE(C24) | M24: =VALUE(D24) | N24: =VALUE(E24) | O24: =VALUE(F24) | P24: =VALUE(G24) | Q24: =VALUE(H24) | R24: =VALUE(I24) | Y24: 2,025.34 | Z24: 1,605.63 | AA24: 609.13 | AB24: -1,176.97 | AC24: 2,197.58 | AD24: 5,083.68 | AE24: 9,531.16 | AF24: 10,386.36 | AG24: 9,067.15 | AH24: 6,620.88 | AI24: 4,830.64
A25: Tax Expenses-Continued Operations
A26: Current Tax | C26: 1.52 | D26: 15.82 | E26: -77.13 | F26: -111.22 | G26: -112.56 | H26: 23.16 | I26: 538.35 | L26: =VALUE(C26) | M26: =VALUE(D26) | N26: =VALUE(E26) | O26: =VALUE(F26) | P26: =VALUE(G26) | Q26: =VALUE(H26) | R26: =VALUE(I26) | Y26: 735.07 | Z26: 578.67 | AA26: 298.35 | AB26: 391.08 | AC26: 968.87 | AD26: 1,923.63 | AE26: 3,063.78 | AF26: 2,664.28 | AG26: 3,648.55 | AH26: 2,020.64 | AI26: 2,261.77
A27: Less: MAT Credit Entitlement | C27: 0 | D27: 0 | E27: 0 | F27: 0 | G27: 0 | H27: 0 | I27: 0 | L27: =VALUE(C27) | M27: =VALUE(D27) | N27: =VALUE(E27) | O27: =VALUE(F27) | P27: =VALUE(G27) | Q27: =VALUE(H27) | R27: =VALUE(I27) | Y27: 0.00 | Z27: 0.00 | AA27: 0.00 | AB27: 0.00 | AC27: 0.00 | AD27: 0.00 | AE27: 0.00 | AF27: 0.00 | AG27: 0.00 | AH27: 0.00 | AI27: 0.00
A28: Deferred Tax | C28: 807.76 | D28: -912.05 | E28: 102.88 | F28: 113.27 | G28: 73 | H28: 188.54 | I28: 0 | L28: =VALUE(C28) | M28: =VALUE(D28) | N28: =VALUE(E28) | O28: =VALUE(F28) | P28: =VALUE(G28) | Q28: =VALUE(H28) | R28: =VALUE(I28) | Y28: 102.25 | Z28: 198.01 | AA28: -167.96 | AB28: -846.63 | AC28: -232.02 | AD28: -316.96 | AE28: -6.32 | AF28: 615.69 | AG28: -636.55 | AH28: 312.39 | AI28: -502.50
A29: Other Direct Taxes | C29: 0 | D29: 0 | E29: 0 | F29: 0 | G29: 0 | H29: 0 | I29: 0 | L29: =VALUE(C29) | M29: =VALUE(D29) | N29: =VALUE(E29) | O29: =VALUE(F29) | P29: =VALUE(G29) | Q29: =VALUE(H29) | R29: =VALUE(I29) | Y29: 0.00 | Z29: 0.00 | AA29: 0.00 | AB29: 0.00 | AC29: 0.00 | AD29: 0.00 | AE29: 0.00 | AF29: 0.00 | AG29: 0.00 | AH29: 7.28 | AI29: 51.86
A30: Total Tax Expenses | C30: 809.28 | D30: -896.23 | E30: 25.75 | F30: 2.05 | G30: -39.56 | H30: 211.7 | I30: 538.35 | L30: =VALUE(C30) | M30: =VALUE(D30) | N30: =VALUE(E30) | O30: =VALUE(F30) | P30: =VALUE(G30) | Q30: =VALUE(H30) | R30: =VALUE(I30) | Y30: 837.32 | Z30: 776.68 | AA30: 130.39 | AB30: -455.55 | AC30: 736.85 | AD30: 1,575.34 | AE30: 2,837.61 | AF30: 3,279.97 | AG30: 3,012.00 | AH30: 2,340.31 | AI30: 1,811.13
A31: Profit/Loss After Tax And Before ExtraOrdinary Items | C31: -1494.07 | D31: -2743.84 | E31: 394.29 | F31: 421.37 | G31: 218.24 | H31: 474.89 | I31: 1539.21 | L31: =VALUE(C31) | M31: =VALUE(D31) | N31: =VALUE(E31) | O31: =VALUE(F31) | P31: =VALUE(G31) | Q31: =VALUE(H31) | R31: =VALUE(I31) | Y31: 1,188.02 | Z31: 828.95 | AA31: 478.74 | AB31: -721.42 | AC31: 1,460.73 | AD31: 3,508.34 | AE31: 6,693.55 | AF31: 7,106.39 | AG31: 6,055.15 | AH31: 4,280.57 | AI31: 3,019.51
A32: Profit/Loss From Continuing Operations | C32: -1494.07 | D32: -2743.84 | E32: 394.29 | F32: 421.37 | G32: 218.24 | H32: 474.89 | I32: 1539.21 | L32: =VALUE(C32) | M32: =VALUE(D32) | N32: =VALUE(E32) | O32: =VALUE(F32) | P32: =VALUE(G32) | Q32: =VALUE(H32) | R32: =VALUE(I32) | Y32: 1,188.02 | Z32: 828.95 | AA32: 478.74 | AB32: -721.42 | AC32: 1,450.44 | AD32: 3,502.34 | AE32: 6,693.10 | AF32: 7,087.26 | AG32: 6,053.36 | AH32: 4,326.92 | AI32: 3,115.17
A33: Profit/Loss For The Period | C33: -1494.07 | D33: -2743.84 | E33: 394.29 | F33: 421.37 | G33: 218.24 | H33: 474.89 | I33: 1539.21 | L33: =VALUE(C33) | M33: =VALUE(D33) | N33: =VALUE(E33) | O33: =VALUE(F33) | P33: =VALUE(G33) | Q33: =VALUE(H33) | R33: =VALUE(I33) | Y33: 1,188.02 | Z33: 828.95 | AA33: 478.74 | AB33: -721.42 | AC33: 1,450.44 | AD33: 3,502.34 | AE33: 6,693.10 | AF33: 7,087.26 | AG33: 6,053.36 | AH33: 4,326.92 | AI33: 3,115.17
A34: Minority Interest | C34: 2.34 | D34: 2.59 | E34: 1.32 | F34: 0 | G34: 0 | H34: 0 | I34: 0 | L34: =VALUE(C34) | M34: =VALUE(D34) | N34: =VALUE(E34) | O34: =VALUE(F34) | P34: =VALUE(G34) | Q34: =VALUE(H34) | R34: =VALUE(I34) | Y34: 2.68 | Z34: 2.97 | AA34: 2.08 | AB34: 1.45 | AC34: 1.94 | AD34: 0.52 | AE34: 0.27 | AF34: 0.18 | AG34: 0.00 | AH34: 0.00 | AI34: 0.00
A35: Consolidated Profit/Loss After MI And Associates | C35: -1466.01 | D35: -2697.11 | E35: 446.03 | F35: 477.39 | G35: 282.22 | H35: 533.9 | I35: 1600.26 | L35: =VALUE(C35) | M35: =VALUE(D35) | N35: =VALUE(E35) | O35: =VALUE(F35) | P35: =VALUE(G35) | Q35: =VALUE(H35) | R35: =VALUE(I35) | Y35: 1,005.10 | Z35: 441.16 | AA35: 457.26 | AB35: -704.13 | AC35: 1,452.38 | AD35: 3,502.86 | AE35: 6,693.37 | AF35: 7,087.44 | AG35: 6,053.36 | AH35: 4,326.92 | AI35: 3,115.17
A36: OTHER ADDITIONAL INFORMATION
A37: EARNINGS PER SHARE
A38: Basic EPS (Rs.) | C38: -4 | D38: -8 | E38: 1 | F38: 1 | G38: 1 | H38: 2 | I38: 5 | L38: =VALUE(C38) | M38: =VALUE(D38) | N38: =VALUE(E38) | O38: =VALUE(F38) | P38: =VALUE(G38) | Q38: =VALUE(H38) | R38: =VALUE(I38) | Y38: 3.00 | Z38: 1.00 | AA38: 1.00 | AB38: -3.00 | AC38: 6.00 | AD38: 14.00 | AE38: 27.00 | AF38: 29.00 | AG38: 25.00 | AH38: 88.00 | AI38: 64.00
A39: Diluted EPS (Rs.) | C39: -4 | D39: -8 | E39: 1 | F39: 1 | G39: 1 | H39: 2 | I39: 5 | L39: =VALUE(C39) | M39: =VALUE(D39) | N39: =VALUE(E39) | O39: =VALUE(F39) | P39: =VALUE(G39) | Q39: =VALUE(H39) | R39: =VALUE(I39) | Y39: 3.00 | Z39: 1.00 | AA39: 1.00 | AB39: -3.00 | AC39: 6.00 | AD39: 14.00 | AE39: 27.00 | AF39: 29.00 | AG39: 25.00 | AH39: 88.00 | AI39: 64.00
A40: DIVIDEND AND DIVIDEND PERCENTAGE
...

Sheet Assumptions
B1: FORECAST ASSUMPTIONS - variable (scenario-driven) & fixed
B3: Scenario Switch | C3: Base | E3: <- toggle Base / Best / Bear and the whole PL, BS & engine recalculate
E4: Active scenario FY2033E: | G4: ="Sales "&TEXT('PL'!P5,"#,##0")&" | EBITDA "&TEXT('PL'!P12,"#,##0")&" | PAT "&TEXT('PL'!P20,"#,##0")
B6: A. VARIABLE ASSUMPTIONS (Base / Best / Bear, selected by Scenario Switch)
B7: ratios / INR Crore | J7: 2027 | K7: 2028 | L7: 2029 | M7: 2030 | N7: 2031 | O7: 2032 | P7: 2033 | Q7: Rationale
B8: Revenue growth % | J8: =IF($C$3="Best",J10,IF($C$3="Bear",J11,J9)) | K8: =IF($C$3="Best",K10,IF($C$3="Bear",K11,K9)) | L8: =IF($C$3="Best",L10,IF($C$3="Bear",L11,L9)) | M8: =IF($C$3="Best",M10,IF($C$3="Bear",M11,M9)) | N8: =IF($C$3="Best",N10,IF($C$3="Bear",N11,N9)) | O8: =IF($C$3="Best",O10,IF($C$3="Bear",O11,O9)) | P8: =IF($C$3="Best",P10,IF($C$3="Bear",P11,P9)) | Q8: Demand driver. Base = order-book-supported double digits tapering; Best = faster execution/new ordering; Bear = slower power capex & execution delays.
B9: Base | J9: 0.15 | K9: 0.14 | L9: 0.13 | M9: 0.12 | N9: 0.11 | O9: 0.1 | P9: 0.09
B10: Best | J10: 0.18 | K10: 0.17 | L10: 0.16 | M10: 0.14 | N10: 0.13 | O10: 0.12 | P10: 0.11
B11: Bear | J11: 0.1 | K11: 0.09 | L11: 0.08 | M11: 0.07 | N11: 0.06 | O11: 0.06 | P11: 0.05
B13: Gross margin % | J13: =IF($C$3="Best",J15,IF($C$3="Bear",J16,J14)) | K13: =IF($C$3="Best",K15,IF($C$3="Bear",K16,K14)) | L13: =IF($C$3="Best",L15,IF($C$3="Bear",L16,L14)) | M13: =IF($C$3="Best",M15,IF($C$3="Bear",M16,M14)) | N13: =IF($C$3="Best",N15,IF($C$3="Bear",N16,N14)) | O13: =IF($C$3="Best",O15,IF($C$3="Bear",O16,O14)) | P13: =IF($C$3="Best",P15,IF($C$3="Bear",P16,P14)) | Q13: Margin driver. Actual FY26 32.0%. Best = favourable mix + benign steel/copper; Bear = commodity inflation & competitive pricing.
B14: Base | J14: 0.325 | K14: 0.33 | L14: 0.335 | M14: 0.34 | N14: 0.34 | O14: 0.345 | P14: 0.35
B15: Best | J15: 0.335 | K15: 0.345 | L15: 0.355 | M15: 0.36 | N15: 0.365 | O15: 0.37 | P15: 0.375
B16: Bear | J16: 0.31 | K16: 0.31 | L16: 0.315 | M16: 0.315 | N16: 0.32 | O16: 0.32 | P16: 0.325
B18: EBITDA margin % | J18: =IF($C$3="Best",J20,IF($C$3="Bear",J21,J19)) | K18: =IF($C$3="Best",K20,IF($C$3="Bear",K21,K19)) | L18: =IF($C$3="Best",L20,IF($C$3="Bear",L21,L19)) | M18: =IF($C$3="Best",M20,IF($C$3="Bear",M21,M19)) | N18: =IF($C$3="Best",N20,IF($C$3="Bear",N21,N19)) | O18: =IF($C$3="Best",O20,IF($C$3="Bear",O21,O19)) | P18: =IF($C$3="Best",P20,IF($C$3="Bear",P21,P19)) | Q18: Operating leverage. Actual FY26 6.9%. Best = strong leverage to low-/mid-teens; Bear = limited leverage if growth disappoints.
B19: Base | J19: 0.08 | K19: 0.09 | L19: 0.1 | M19: 0.11 | N19: 0.115 | O19: 0.12 | P19: 0.125
B20: Best | J20: 0.095 | K20: 0.11 | L20: 0.12 | M20: 0.13 | N20: 0.135 | O20: 0.14 | P20: 0.145
B21: Bear | J21: 0.065 | K21: 0.07 | L21: 0.078 | M21: 0.085 | N21: 0.09 | O21: 0.095 | P21: 0.1
B23: Receivable days | J23: =IF($C$3="Best",J25,IF($C$3="Bear",J26,J24)) | K23: =IF($C$3="Best",K25,IF($C$3="Bear",K26,K24)) | L23: =IF($C$3="Best",L25,IF($C$3="Bear",L26,L24)) | M23: =IF($C$3="Best",M25,IF($C$3="Bear",M26,M24)) | N23: =IF($C$3="Best",N25,IF($C$3="Bear",N26,N24)) | O23: =IF($C$3="Best",O25,IF($C$3="Bear",O26,O24)) | P23: =IF($C$3="Best",P25,IF($C$3="Bear",P26,P24)) | Q23: Collections cycle. Best = faster realisation from PSU/SEB customers; Bear = stretched receivables in a weak cycle.
B24: Base | J24: 73 | K24: 73 | L24: 73 | M24: 72 | N24: 72 | O24: 72 | P24: 72
B25: Best | J25: 70 | K25: 68 | L25: 66 | M25: 65 | N25: 64 | O25: 63 | P25: 62
B26: Bear | J26: 80 | K26: 82 | L26: 84 | M26: 85 | N26: 86 | O26: 86 | P26: 86
B28: Inventory days (on COGS) | J28: =IF($C$3="Best",J30,IF($C$3="Bear",J31,J29)) | K28: =IF($C$3="Best",K30,IF($C$3="Bear",K31,K29)) | L28: =IF($C$3="Best",L30,IF($C$3="Bear",L31,L29)) | M28: =IF($C$3="Best",M30,IF($C$3="Bear",M31,M29)) | N28: =IF($C$3="Best",N30,IF($C$3="Bear",N31,N29)) | O28: =IF($C$3="Best",O30,IF($C$3="Bear",O31,O29)) | P28: =IF($C$3="Best",P30,IF($C$3="Bear",P31,P29)) | Q28: Project inventory cycle. Best = tighter planning/execution; Bear = slow-moving project inventory build-up.
B29: Base | J29: 210 | K29: 205 | L29: 202 | M29: 200 | N29: 198 | O29: 195 | P29: 193
B30: Best | J30: 195 | K30: 188 | L30: 182 | M30: 178 | N30: 175 | O30: 172 | P30: 170
B31: Bear | J31: 225 | K31: 225 | L31: 222 | M31: 220 | N31: 218 | O31: 215 | P31: 213
B34: B. FIXED ASSUMPTIONS (structural / policy - constant across scenarios)
B35: ratios / INR Crore | J35: 2027 | K35: 2028 | L35: 2029 | M35: 2030 | N35: 2031 | O35: 2032 | P35: 2033 | Q35: Rationale
B36: Employee cost % of sales | J36: 0.185 | K36: 0.18 | L36: 0.175 | M36: 0.17 | N36: 0.165 | O36: 0.16 | P36: 0.155 | Q36: Largely fixed cost base; declines as % as sales scale (FY26 19.1%).
B37: Other income % of sales | J37: 0.022 | K37: 0.022 | L37: 0.022 | M37: 0.022 | N37: 0.022 | O37: 0.022 | P37: 0.022 | Q37: Treasury income on cash (~2.2%).
B38: Payable days (on COGS) | J38: 167 | K38: 167 | L38: 167 | M38: 167 | N38: 167 | O38: 167 | P38: 167 | Q38: Supplier credit ~167 days (FY26 actual).
B39: Other current assets % of sales | J39: 0.57 | K39: 0.56 | L39: 0.55 | M39: 0.54 | N39: 0.53 | O39: 0.52 | P39: 0.51 | Q39: Unbilled/contract assets & advances; ~58% of sales declining.
B40: Other current liabilities % of sales | J40: 0.4 | K40: 0.4 | L40: 0.39 | M40: 0.39 | N40: 0.38 | O40: 0.38 | P40: 0.37 | Q40: Customer advances & provisions; key WC funding (~41%).
B41: Other non-current assets growth % | J41: 0.03 | K41: 0.03 | L41: 0.03 | M41: 0.03 | N41: 0.03 | O41: 0.03 | P41: 0.03 | Q41: Deferred tax assets, legacy LT receivables; slow growth.
B42: Other non-current liabilities growth % | J42: 0.04 | K42: 0.04 | L42: 0.04 | M42: 0.04 | N42: 0.04 | O42: 0.04 | P42: 0.04 | Q42: Long-term advances/deferred; moderate growth.
B43: LT provisions growth % | J43: 0.03 | K43: 0.03 | L43: 0.03 | M43: 0.03 | N43: 0.03 | O43: 0.03 | P43: 0.03 | Q43: Warranty & employee-benefit provisions.
B44: Capital expenditure (Rs cr) | J44: 600 | K44: 700 | L44: 750 | M44: 800 | N44: 850 | O44: 900 | P44: 950 | Q44: Modernisation + renewables/defence capacity; internally funded.
B45: Depreciation % of opening net block | J45: 0.095 | K45: 0.095 | L45: 0.095 | M45: 0.095 | N45: 0.095 | O45: 0.095 | P45: 0.095 | Q45: ~ historical D&A / net block (9-10%).
B46: CWIP closing (Rs cr) | J46: 400 | K46: 400 | L46: 400 | M46: 400 | N46: 400 | O46: 400 | P46: 400 | Q46: Steady-state low.
... B52: Dividend payout % of PAT | J52: 0.3 | K52: 0.3 | L52: 0.3 | M52: 0.3 | N52: 0.3 | O52: 0.3 | P52: 0.3 | Q52: CPSE/DIPAM policy ~30%.
B54: C. WACC & VALUATION (fixed)
...

Sheet Forecast Engine
B1: FORECAST ENGINE (2026 seed = actuals; 2027-2033 driven by Assumptions/Scenario)
I3: 2026 | J3: 2027 | K3: 2028 | L3: 2029 | M3: 2030 | N3: 2031 | O3: 2032 | P3: 2033
B4: Revenue | I4: ='PL'!I5 | J4: =I4*(1+'Assumptions'!J8) | K4: =J4*(1+'Assumptions'!K8) | L4: =K4*(1+'Assumptions'!L8) | M4: =L4*(1+'Assumptions'!M8) | N4: =M4*(1+'Assumptions'!N8) | O4: =N4*(1+'Assumptions'!O8) | P4: =O4*(1+'Assumptions'!P8)
B5: COGS | I5: =-'PL'!I6 | J5: =J4*(1-'Assumptions'!J13) | K5: =K4*(1-'Assumptions'!K13) | L5: =L4*(1-'Assumptions'!L13) | M5: =M4*(1-'Assumptions'!M13) | N5: =N4*(1-'Assumptions'!N13) | O5: =O4*(1-'Assumptions'!O13) | P5: =P4*(1-'Assumptions'!P13)
B6: Gross | I6: =I4-I5 | J6: =J4-J5 | K6: =K4-K5 | L6: =L4-L5 | M6: =M4-M5 | N6: =N4-N5 | O6: =O4-O5 | P6: =P4-P5
B7: Employee | I7: =-'PL'!I9 | J7: =J4*'Assumptions'!J36 | K7: =K4*'Assumptions'!K36 | L7: =L4*'Assumptions'!L36 | M7: =M4*'Assumptions'!M36 | N7: =N4*'Assumptions'!N36 | O7: =O4*'Assumptions'!O36 | P7: =P4*'Assumptions'!P36
B8: EBITDA | I8: ='PL'!I12 | J8: =J4*'Assumptions'!J18 | K8: =K4*'Assumptions'!K18 | L8: =L4*'Assumptions'!L18 | M8: =M4*'Assumptions'!M18 | N8: =N4*'Assumptions'!N18 | O8: =O4*'Assumptions'!O18 | P8: =P4*'Assumptions'!P18
B9: SGA | I9: =I6-I7-I8 | J9: =J6-J7-J8 | K9: =K6-K7-K8 | L9: =L6-L7-L8 | M9: =M6-M7-M8 | N9: =N6-N7-N8 | O9: =O6-O7-O8 | P9: =P6-P7-P8
B11: NBopen | I11: ='BS'!I30 | J11: =I14 | K11: =J14 | L11: =K14 | M11: =L14 | N11: =M14 | O11: =N14 | P11: =O14
B12: Capex | I12: 0 | J12: ='Assumptions'!J44 | K12: ='Assumptions'!K44 | L12: ='Assumptions'!L44 | M12: ='Assumptions'!M44 | N12: ='Assumptions'!N44 | O12: ='Assumptions'!O44 | P12: ='Assumptions'!P44
B13: Dep | I13: =-'PL'!I13 | J13: =J11*'Assumptions'!J45 | K13: =K11*'Assumptions'!K45 | L13: =L11*'Assumptions'!L45 | M13: =M11*'Assumptions'!M45 | N13: =N11*'Assumptions'!N45 | O13: =O11*'Assumptions'!O45 | P13: =P11*'Assumptions'!P45
B14: NBclose | I14: ='BS'!I30 | J14: =J11+J12-J13 | K14: =K11+K12-K13 | L14: =L11+L12-L13 | M14: =M11+M12-M13 | N14: =N11+N12-N13 | O14: =O11+O12-O13 | P14: =P11+P12-P13
B15: EBIT | I15: =I8-I13 | J15: =J8-J13 | K15: =K8-K13 | L15: =L8-L13 | M15: =M8-M13 | N15: =N8-N13 | O15: =O8-O13 | P15: =P8-P13
B17: Dopen | I17: ='BS'!I14+'BS'!I19 | J17: =I19 | K17: =J19 | L17: =K19 | M17: =L19 | N17: =M19 | O17: =N19 | P17: =O19
B18: Repay | I18: 0 | J18: ='Assumptions'!J49 | K18: ='Assumptions'!K49 | L18: ='Assumptions'!L49 | M18: ='Assumptions'!M49 | N18: ='Assumptions'!N49 | O18: ='Assumptions'!O49 | P18: ='Assumptions'!P49
B19: Dclose | I19: =I17-I18 | J19: =J17-J18 | K19: =K17-K18 | L19: =L17-L18 | M19: =M17-M18 | N19: =N17-N18 | O19: =O17-O18 | P19: =P17-P18
B20: LTbor | I20: ='BS'!I14 | J20: =J19*'Assumptions'!J48 | K20: =K19*'Assumptions'!K48 | L20: =L19*'Assumptions'!L48 | M20: =M19*'Assumptions'!M48 | N20: =N19*'Assumptions'!N48 | O20: =O19*'Assumptions'!O48 | P20: =P19*'Assumptions'!P48
B21: STbor | I21: =I19-I20 | J21: =J19-J20 | K21: =K19-K20 | L21: =L19-L20 | M21: =M19-M20 | N21: =N19-N20 | O21: =O19-O20 | P21: =P19-P20
B22: Int | I22: =-'PL'!I16 | J22: =J17*'Assumptions'!J50 | K22: =K17*'Assumptions'!K50 | L22: =L17*'Assumptions'!L50 | M22: =M17*'Assumptions'!M50 | N22: =N17*'Assumptions'!N50 | O22: =O17*'Assumptions'!O50 | P22: =P17*'Assumptions'!P50
B23: OthInc | I23: ='PL'!I15 | J23: =J4*'Assumptions'!J37 | K23: =K4*'Assumptions'!K37 | L23: =L4*'Assumptions'!L37 | M23: =M4*'Assumptions'!M37 | N23: =N4*'Assumptions'!N37 | O23: =O4*'Assumptions'!O37 | P23: =P4*'Assumptions'!P37
B24: PBT | I24: =I15+I23-I22 | J24: =J15+J23-J22 | K24: =K15+K23-K22 | L24: =L15+L23-L22 | M24: =M15+M23-M22 | N24: =N15+N23-N22 | O24: =O15+O23-O22 | P24: =P15+P23-P22
B25: Tax | I25: =-'PL'!I18 | J25: =J24*'Assumptions'!J51 | K25: =K24*'Assumptions'!K51 | L25: =L24*'Assumptions'!L51 | M25: =M24*'Assumptions'!M51 | N25: =N24*'Assumptions'!N51 | O25: =O24*'Assumptions'!O51 | P25: =P24*'Assumptions'!P51
B26: PAT | I26: =I24-I25 | J26: =J24-J25 | K26: =K24-K25 | L26: =L24-L25 | M26: =M24-M25 | N26: =N24-N25 | O26: =O24-O25 | P26: =P24-P25
B27: Div | I27: 0 | J27: =J26*'Assumptions'!J52 | K27: =K26*'Assumptions'!K52 | L27: =L26*'Assumptions'!L52 | M27: =M26*'Assumptions'!M52 | N27: =N26*'Assumptions'!N52 | O27: =O26*'Assumptions'!O52 | P27: =P26*'Assumptions'!P52
B29: ResOpen | I29: ='BS'!I9 | J29: =I30 | K29: =J30 | L29: =K30 | M29: =L30 | N29: =M30 | O29: =N30 | P29: =O30
B30: ResClose | I30: ='BS'!I9 | J30: =J29+J26-J27 | K30: =K29+K26-K27 | L30: =L29+L26-L27 | M30: =M29+M26-M27 | N30: =N29+N26-N27 | O30: =O29+O26-O27 | P30: =P29+P26-P27
B32: Recv | I32: ='BS'!I38 | J32: ='Assumptions'!J23/365*J4 | K32: ='Assumptions'!K23/365*K4 | L32: ='Assumptions'!L23/365*L4 | M32: ='Assumptions'!M23/365*M4 | N32: ='Assumptions'!N23/365*N4 | O32: ='Assumptions'!O23/365*O4 | P32: ='Assumptions'!P23/365*P4
B33: Inv | I33: ='BS'!I39 | J33: ='Assumptions'!J28/365*J5 | K33: ='Assumptions'!K28/365*K5 | L33: ='Assumptions'!L28/365*L5 | M33: ='Assumptions'!M28/365*M5 | N33: ='Assumptions'!N28/365*N5 | O33: ='Assumptions'!O28/365*O5 | P33: ='Assumptions'!P28/365*P5
B34: Pay | I34: ='BS'!I20 | J34: ='Assumptions'!J38/365*J5 | K34: ='Assumptions'!K38/365*K5 | L34: ='Assumptions'!L38/365*L5 | M34: ='Assumptions'!M38/365*M5 | N34: ='Assumptions'!N38/365*N5 | O34: ='Assumptions'!O38/365*O5 | P34: ='Assumptions'!P38/365*P5
B35: OCA | I35: ='BS'!I40 | J35: =J4*'Assumptions'!J39 | K35: =K4*'Assumptions'!K39 | L35: =L4*'Assumptions'!L39 | M35: =M4*'Assumptions'!M39 | N35: =N4*'Assumptions'!N39 | O35: =O4*'Assumptions'!O39 | P35: =P4*'Assumptions'!P39
B36: OCL | I36: ='BS'!I21 | J36: =J4*'Assumptions'!J40 | K36: =K4*'Assumptions'!K40 | L36: =L4*'Assumptions'!L40 | M36: =M4*'Assumptions'!M40 | N36: =N4*'Assumptions'!N40 | O36: =O4*'Assumptions'!O40 | P36: =P4*'Assumptions'!P40
B37: ONCA | I37: ='BS'!I34 | J37: =I37*(1+'Assumptions'!J41) | K37: =J37*(1+'Assumptions'!K41) | L37: =K37*(1+'Assumptions'!L41) | M37: =L37*(1+'Assumptions'!M41) | N37: =M37*(1+'Assumptions'!N41) | O37: =N37*(1+'Assumptions'!O41) | P37: =O37*(1+'Assumptions'!P41)
B38: ONCL | I38: ='BS'!I16 | J38: =I38*(1+'Assumptions'!J42) | K38: =J38*(1+'Assumptions'!K42) | L38: =K38*(1+'Assumptions'!L42) | M38: =L38*(1+'Assumptions'!M42) | N38: =M38*(1+'Assumptions'!N42) | O38: =N38*(1+'Assumptions'!O42) | P38: =O38*(1+'Assumptions'!P42)
B39: LTprov | I39: ='BS'!I15 | J39: =I39*(1+'Assumptions'!J43) | K39: =J39*(1+'Assumptions'!K43) | L39: =K39*(1+'Assumptions'!L43) | M39: =L39*(1+'Assumptions'!M43) | N39: =M39*(1+'Assumptions'!N43) | O39: =N39*(1+'Assumptions'!O43) | P39: =O39*(1+'Assumptions'!P43)
B40: CWIP | I40: ='BS'!I31 | J40: ='Assumptions'!J46 | K40: ='Assumptions'!K46 | L40: ='Assumptions'!L46 | M40: ='Assumptions'!M46 | N40: ='Assumptions'!N46 | O40: ='Assumptions'!O46 | P40: ='Assumptions'!P46
B41: Invst | I41: ='BS'!I32 | J41: ='Assumptions'!J47 | K41: ='Assumptions'!K47 | L41: ='Assumptions'!L47 | M41: ='Assumptions'!M47 | N41: ='Assumptions'!N47 | O41: ='Assumptions'!O47 | P41: ='Assumptions'!P47
B42: NWC | I42: =(I32+I33+I35+I37)-(I34+I36+I38+I39) | J42: =(J32+J33+J35+J37)-(J34+J36+J38+J39) | K42: =(K32+K33+K35+K37)-(K34+K36+K38+K39) | L42: =(L32+L33+L35+L37)-(L34+L36+L38+L39) | M42: =(M32+M33+M35+M37)-(M34+M36+M38+M39) | N42: =(N32+N33+N35+N37)-(N34+N36+N38+N39) | O42: =(O32+O33+O35+O37)-(O34+O36+O38+O39) | P42: =(P32+P33+P35+P37)-(P34+P36+P38+P39)
B43: dNWC | J43: =-(J42-I42) | K43: =-(K42-J42) | L43: =-(L42-K42) | M43: =-(M42-L42) | N43: =-(N42-M42) | O43: =-(O42-N42) | P43: =-(P42-O42)
B45: CFO | J45: =J26+J13+J43 | K45: =K26+K13+K43 | L45: =L26+L13+L43 | M45: =M26+M13+M43 | N45: =N26+N13+N43 | O45: =O26+O13+O43 | P45: =P26+P13+P43
B46: CFI | J46: =-J12-(J40-I40)-(J41-I41) | K46: =-K12-(K40-J40)-(K41-J41) | L46: =-L12-(L40-K40)-(L41-K41) | M46: =-M12-(M40-L40)-(M41-L41) | N46: =-N12-(N40-M40)-(N41-M41) | O46: =-O12-(O40-N40)-(O41-N41) | P46: =-P12-(P40-O40)-(P41-O41)
...

Sheet PL
B2: Income Statement
A4: x | B4: Particulars | C4: 2020 | D4: =C4+1 | E4: =D4+1 | F4: =E4+1 | G4: =F4+1 | H4: =G4+1 | I4: =H4+1 | J4: =I4+1 | K4: =J4+1 | ... Q4: =P4+1
B5: Sales | C5: 21463.14 | D5: 17308.69 | E5: 21211.09 | F5: 23364.94 | G5: 23892.78 | H5: 28339.48 | I5: 33782.18 | J5: ='Forecast Engine'!J4 | K5: ='Forecast Engine'!K4 | L5: ='Forecast Engine'!L4 | M5: ='Forecast Engine'!M4 | N5: ='Forecast Engine'!N4 | O5: ='Forecast Engine'!O4 | P5: ='Forecast Engine'!P4
B6: Total COGS | C6: -14720.84 | D6: -12373.6 | E6: -15374.63 | F6: -16971.79 | G6: -17472.26 | H6: -19599.52 | I6: -22983.09 | J6: =-'Forecast Engine'!J5 | K6: =-'Forecast Engine'!K5 | L6: =-'Forecast Engine'!L5 | M6: =-'Forecast Engine'!M5 | N6: =-'Forecast Engine'!N5 | O6: =-'Forecast Engine'!O5 | P6: =-'Forecast Engine'!P5
A7: x | B7: Gross Profit | C7: =SUM(C5:C6) | D7: =SUM(D5:D6) | E7: =SUM(E5:E6) | F7: =SUM(F5:F6) | G7: =SUM(G5:G6) | H7: =SUM(H5:H6) | I7: =SUM(I5:I6) | J7: =J5+J6 | K7: =K5+K6 | L7: =L5+L6 | M7: =M5+M6 | N7: =N5+N6 | O7: =O5+O6 | P7: =P5+P6 | Q7: =SUM(Q5:Q6)
B8: Operating Expenes
B9: Employee Cost | C9: -5431.88 | D9: -5378.15 | E9: -5519.05 | F9: -5700.63 | G9: -5628.84 | H9: -5923.42 | I9: -6467.62 | J9: =-'Forecast Engine'!J7 | K9: =-'Forecast Engine'!K7 | L9: =-'Forecast Engine'!L7 | M9: =-'Forecast Engine'!M7 | N9: =-'Forecast Engine'!N7 | O9: =-'Forecast Engine'!O7 | P9: =-'Forecast Engine'!P7
B10: Selling and admin | C10: -1443.57 | D10: -2605.41 | E10: 510.63 | F10: 351.13 | G10: -80.79 | H10: -1417.22 | I10: -1989.28 | J10: =-'Forecast Engine'!J9 | K10: =-'Forecast Engine'!K9 | L10: =-'Forecast Engine'!L9 | M10: =-'Forecast Engine'!M9 | N10: =-'Forecast Engine'!N9 | O10: =-'Forecast Engine'!O9 | P10: =-'Forecast Engine'!P9
B11: Total Operating Expenses | C11: =SUM(C9:C10) | D11: =SUM(D9:D10) | E11: =SUM(E9:E10) | F11: =SUM(F9:F10) | G11: =SUM(G9:G10) | H11: =SUM(H9:H10) | I11: =SUM(I9:I10) | J11: =J9+J10 | K11: =K9+K10 | L11: =L9+L10 | M11: =M9+M10 | N11: =N9+N10 | O11: =O9+O10 | P11: =P9+P10 | Q11: =SUM(Q9:Q10)
A12: x | B12: EBITDA | C12: =C7+C11 | D12: =D7+D11 | E12: =E7+E11 | F12: =F7+F11 | G12: =G7+G11 | H12: =H7+H11 | I12: =I7+I11 | J12: =J7+J11 | ... P12: =P7+P11
B13: Depreciation & Amortization | C13: -503.27 | D13: -473.25 | E13: -314.12 | F13: -260.34 | G13: -248.9 | H13: -271.96 | I13: -315.87 | J13: =-'Forecast Engine'!J13 | K13: =-'Forecast Engine'!K13 | L13: =-'Forecast Engine'!L13 | M13: =-'Forecast Engine'!M13 | N13: =-'Forecast Engine'!N13 | O13: =-'Forecast Engine'!O13 | P13: =-'Forecast Engine'!P13
B14: EBIT | C14: =C12+C13 | D14: =D12+D13 | E14: =E12+E13 | F14: =F12+F13 | G14: =G12+G13 | H14: =H12+H13 | I14: =I12+I13 | J14: =J12+J13 | ... Q14: =Q12+Q13
B15: Other Income | C15: 590.02 | D15: 392.56 | E15: 404.67 | F15: 544.49 | G15: 608.31 | H15: 524.32 | I15: 868.7 | J15: ='Forecast Engine'!J23 | K15: ='Forecast Engine'!K23 | L15: ='Forecast Engine'!L23 | M15: ='Forecast Engine'!M23 | N15: ='Forecast Engine'!N23 | O15: ='Forecast Engine'!O23 | P15: ='Forecast Engine'!P23
B16: Interest Paid | C16: -612.67 | D16: -466.56 | E16: -448.13 | F16: -612.19 | G16: -827.64 | H16: -906.08 | I16: -756.41 | J16: =-'Forecast Engine'!J22 | K16: =-'Forecast Engine'!K22 | L16: =-'Forecast Engine'!L22 | M16: =-'Forecast Engine'!M22 | N16: =-'Forecast Engine'!N22 | O16: =-'Forecast Engine'!O22 | P16: =-'Forecast Engine'!P22
A17: x | B17: Profit Before Tax (PBT) | C17: =SUM(C14:C16) | D17: =SUM(D14:D16) | E17: =SUM(E14:E16) | F17: =SUM(F14:F16) | G17: =SUM(G14:G16) | H17: =SUM(H14:H16) | I17: =SUM(I14:I16) | J17: =J14+J15+J16 | K17: =K14+K15+K16 | L17: =L14+L15+L16 | M17: =M14+M15+M16 | N17: =N14+N15+N16 | O17: =O14+O15+O16 | P17: =P14+P15+P16 | Q17: =SUM(Q14:Q16)
B18: Tax | C18: -809.28 | D18: 896.23 | E18: -25.75 | F18: -61.49 | G18: 39.56 | H18: -211.7 | I18: -538.35 | J18: =-'Forecast Engine'!J25 | K18: =-'Forecast Engine'!K25 | L18: =-'Forecast Engine'!L25 | M18: =-'Forecast Engine'!M25 | N18: =-'Forecast Engine'!N25 | O18: =-'Forecast Engine'!O25 | P18: =-'Forecast Engine'!P25
B19: Adjustments | J19: 0 | K19: 0 | L19: 0 | M19: 0 | N19: 0 | O19: 0 | P19: 0
A20: x | B20: Profit After Tax (PAT) | C20: =SUM(C17:C19) | D20: =SUM(D17:D19) | E20: =SUM(E17:E19) | F20: =SUM(F17:F19) | G20: =SUM(G17:G19) | H20: =SUM(H17:H19) | I20: =SUM(I17:I19) | J20: =J17+J18+J19 | K20: =K17+K18+K19 | L20: =L17+L18+L19 | M20: =M17+M18+M19 | N20: =N17+N18+N19 | O20: =O17+O18+O19 | P20: =P17+P18+P19 | Q20: =SUM(Q17:Q19)

Sheet BS
B2: Balance Sheet
B4: Particulars | C4: 2020 | D4: =C4+1 | E4: =D4+1 | F4: =E4+1 | G4: =F4+1 | H4: =G4+1 | I4: =H4+1 | J4: =I4+1 | K4: =J4+1 | ... Q4: =P4+1
A6: x | B6: Equities & Liablilities
B7: Shareholders' Fund
B8: Share Capital | C8: 696.41 | D8: 696.41 | E8: 696.41 | F8: 696.41 | G8: 696.41 | H8: 696.41 | I8: 696.41 | J8: 696.4 | K8: 696.4 | L8: 696.4 | M8: 696.4 | N8: 696.4 | O8: 696.4 | P8: 696.4
B9: Reserve & Surplus | C9: 27964.31 | D9: 25287.25 | E9: 25810.19 | F9: 23681.85 | G9: 23742.24 | H9: 24025.75 | I9: 25450.19 | J9: ='Forecast Engine'!J30 | K9: ='Forecast Engine'!K30 | L9: ='Forecast Engine'!L30 | M9: ='Forecast Engine'!M30 | N9: ='Forecast Engine'!N30 | O9: ='Forecast Engine'!O30 | P9: ='Forecast Engine'!P30
B10: Total Shareholders' Fund | C10: =SUM(C8:C9) | D10: =SUM(D8:D9) | E10: =SUM(E8:E9) | F10: =SUM(F8:F9) | G10: =SUM(G8:G9) | H10: =SUM(H8:H9) | I10: =SUM(I8:I9) | J10: =J8+J9 | K10: =K8+K9 | L10: =L8+L9 | M10: =M8+M9 | N10: =N8+N9 | O10: =O8+O9 | P10: =P8+P9 | Q10: =SUM(Q8:Q9)
A12: x | B12: Liabilities
B13: Non-Current Liabilities
B14: LT borrowings | C14: 0 | D14: 0 | E14: 0 | F14: 0 | G14: 0 | H14: 0 | I14: 168.18 | J14: ='Forecast Engine'!J20 | K14: ='Forecast Engine'!K20 | L14: ='Forecast Engine'!L20 | M14: ='Forecast Engine'!M20 | N14: ='Forecast Engine'!N20 | O14: ='Forecast Engine'!O20 | P14: ='Forecast Engine'!P20
B15: LT provisions | C15: 4225.16 | D15: 3925.56 | E15: 3771.21 | F15: 4101.02 | G15: 2489.08 | H15: 2585.56 | I15: 2354.62 | J15: ='Forecast Engine'!J39 | K15: ='Forecast Engine'!K39 | L15: ='Forecast Engine'!L39 | M15: ='Forecast Engine'!M39 | N15: ='Forecast Engine'!N39 | O15: ='Forecast Engine'!O39 | P15: ='Forecast Engine'!P39
B16: Other non current liabilities | C16: 4263.27 | D16: 4982.75 | E16: 4594.8 | F16: 5089.29 | G16: 6744.96 | H16: 12549.87 | I16: 15214.03 | J16: ='Forecast Engine'!J38 | K16: ='Forecast Engine'!K38 | L16: ='Forecast Engine'!L38 | M16: ='Forecast Engine'!M38 | N16: ='Forecast Engine'!N38 | O16: ='Forecast Engine'!O38 | P16: ='Forecast Engine'!P38
B17: Total Non-Current Liabilities | C17: =SUM(C14:C16) | D17: =SUM(D14:D16) | E17: =SUM(E14:E16) | F17: =SUM(F14:F16) | G17: =SUM(G14:G16) | H17: =SUM(H14:H16) | I17: =SUM(I14:I16) | J17: =J14+J15+J16 | K17: =K14+K15+K16 | L17: =L14+L15+L16 | M17: =M14+M15+M16 | N17: =N14+N15+N16 | O17: =O14+O15+O16 | P17: =P14+P15+P16 | Q17: =SUM(Q14:Q16)
B18: Current Liabilities
B19: ST borrowings | C19: 4947.92 | D19: 4849.28 | E19: 4745 | F19: 5385 | G19: 8808 | H19: 8795 | I19: 8018.77 | J19: ='Forecast Engine'!J21 | K19: ='Forecast Engine'!K21 | L19: ='Forecast Engine'!L21 | M19: ='Forecast Engine'!M21 | N19: ='Forecast Engine'!N21 | O19: ='Forecast Engine'!O21 | P19: ='Forecast Engine'!P21
B20: Trade Payables | C20: 8829.16 | D20: 6683.51 | E20: 7749.59 | F20: 9895.83 | G20: 8696.24 | H20: 9540.92 | I20: 10491.6 | J20: ='Forecast Engine'!J34 | K20: ='Forecast Engine'!K34 | L20: ='Forecast Engine'!L34 | M20: ='Forecast Engine'!M34 | N20: ='Forecast Engine'!N34 | O20: ='Forecast Engine'!O34 | P20: ='Forecast Engine'!P34
B21: Other Current Liabilities (proviso, advances) | C21: 8831.4 | D21: 8827.11 | E21: 8876.56 | F21: 8070.62 | G21: 7828.57 | H21: 9889.67 | I21: 13791.81 | J21: ='Forecast Engine'!J36 | K21: ='Forecast Engine'!K36 | L21: ='Forecast Engine'!L36 | M21: ='Forecast Engine'!M36 | N21: ='Forecast Engine'!N36 | O21: ='Forecast Engine'!O36 | P21: ='Forecast Engine'!P36
B22: Total Current Liabilities | C22: =SUM(C19:C21) | D22: =SUM(D19:D21) | E22: =SUM(E19:E21) | F22: =SUM(F19:F21) | G22: =SUM(G19:G21) | H22: =SUM(H19:H21) | I22: =SUM(I19:I21) | J22: =J19+J20+J21 | K22: =K19+K20+K21 | L22: =L19+L20+L21 | M22: =M19+M20+M21 | N22: =N19+N20+N21 | O22: =O19+O20+O21 | P22: =P19+P20+P21 | Q22: =SUM(Q19:Q21)
B23: Total Liabilities | C23: =C17+C22 | D23: =D17+D22 | E23: =E17+E22 | F23: =F17+F22 | G23: =G17+G22 | H23: =H17+H22 | I23: =I17+I22 | J23: =J17+J22 | ... Q23: =Q17+Q22
A25: x | B25: Total Equity & Liabilities | C25: =C10+C23 | D25: =D10+D23 | E25: =E10+E23 | F25: =F10+F23 | G25: =G10+G23 | H25: =H10+H23 | I25: =I10+I23 | J25: =J10+J23 | ... Q25: =Q10+Q23
B27: Assets
B28: Non-Current Assets
B29: Fixed Assets
B30: Property Plant & Equip | C30: 2817 | D30: 2491 | E30: 2398 | F30: 2476 | G30: 2574 | H30: 2947 | I30: 3094 | J30: ='Forecast Engine'!J14 | K30: ='Forecast Engine'!K14 | L30: ='Forecast Engine'!L14 | M30: ='Forecast Engine'!M14 | N30: ='Forecast Engine'!N14 | O30: ='Forecast Engine'!O14 | P30: ='Forecast Engine'!P14
B31: Capital Work in Progress | C31: 314 | D31: 420 | E31: 431 | F31: 354 | G31: 308 | H31: 195 | I31: 399 | J31: ='Forecast Engine'!J40 | K31: ='Forecast Engine'!K40 | L31: ='Forecast Engine'!L40 | M31: ='Forecast Engine'!M40 | N31: ='Forecast Engine'!N40 | O31: ='Forecast Engine'!O40 | P31: ='Forecast Engine'!P40
B32: Investments | C32: 162 | D32: 185 | E32: 205 | F32: 235 | G32: 256 | H32: 276 | I32: 302 | J32: ='Forecast Engine'!J41 | K32: ='Forecast Engine'!K41 | L32: ='Forecast Engine'!L41 | M32: ='Forecast Engine'!M41 | N32: ='Forecast Engine'!N41 | O32: ='Forecast Engine'!O41 | P32: ='Forecast Engine'!P41
B33: Total Fixed Assets | C33: =SUM(C30:C32) | D33: =SUM(D30:D32) | E33: =SUM(E30:E32) | F33: =SUM(F30:F32) | G33: =SUM(G30:G32) | H33: =SUM(H30:H32) | I33: =SUM(I30:I32) | J33: =J30+J31+J32 | K33: =K30+K31+K32 | L33: =L30+L31+L32 | M33: =M30+M31+M32 | N33: =N30+N31+N32 | O33: =O30+O31+O32 | P33: =P30+P31+P32 | Q33: =SUM(Q30:Q32)
B34: Other Non Current Assets | C34: 23737.12 | D34: 23784.5 | E34: 25339.12 | F34: 23763.48 | G34: 21295.77 | H34: 21871.68 | I34: 20935.26 | J34: ='Forecast Engine'!J37 | K34: ='Forecast Engine'!K37 | L34: ='Forecast Engine'!L37 | M34: ='Forecast Engine'!M37 | N34: ='Forecast Engine'!N37 | O34: ='Forecast Engine'!O37 | P34: ='Forecast Engine'!P37
B35: Total Non Current Assets | C35: =SUM(C33:C34) | D35: =SUM(D33:D34) | E35: =SUM(E33:E34) | F35: =SUM(F33:F34) | G35: =SUM(G33:G34) | H35: =SUM(H33:H34) | I35: =SUM(I33:I34) | J35: =J33+J34 | K35: =K33+K34 | L35: =L33+L34 | M35: =M33+M34 | N35: =N33+N34 | O35: =O33+O34 | P35: =P33+P34 | Q35: =SUM(Q33:Q34)
B37: Current Assets
B38: Accounts Receivables | C38: 7108.6 | D38: 4035.07 | E38: 3024.75 | F38: 3128.35 | G38: 4785.38 | H38: 5884.35 | I38: 6796.27 | J38: ='Forecast Engine'!J32 | K38: ='Forecast Engine'!K32 | L38: ='Forecast Engine'!L32 | M38: ='Forecast Engine'!M32 | N38: ='Forecast Engine'!N32 | O38: ='Forecast Engine'!O32 | P38: ='Forecast Engine'!P32
B39: Inventories | C39: 8908.23 | D39: 7194.45 | E39: 6560.21 | F39: 6755.9 | G39: 7220.57 | H39: 9869.49 | I39: 13334.58 | J39: ='Forecast Engine'!J33 | K39: ='Forecast Engine'!K33 | L39: ='Forecast Engine'!L33 | M39: ='Forecast Engine'!M33 | N39: ='Forecast Engine'!N33 | O39: ='Forecast Engine'!O33 | P39: ='Forecast Engine'!P33
B40: Other Current Assets | C40: 10292.09 | D40: 10440.4 | E40: 11131.99 | F40: 13564.71 | G40: 16408.31 | H40: 19427.25 | I40: 19457.88 | J40: ='Forecast Engine'!J35 | K40: ='Forecast Engine'!K35 | L40: ='Forecast Engine'!L35 | M40: ='Forecast Engine'!M35 | N40: ='Forecast Engine'!N35 | O40: ='Forecast Engine'!O35 | P40: ='Forecast Engine'!P35
B41: Cash Balance | C41: 6418.59 | D41: 6701.45 | E41: 7153.69 | F41: 6642.58 | G41: 6157.47 | H41: 7612.41 | I41: 11866.62 | J41: ='Forecast Engine'!J50 | K41: ='Forecast Engine'!K50 | L41: ='Forecast Engine'!L50 | M41: ='Forecast Engine'!M50 | N41: ='Forecast Engine'!N50 | O41: ='Forecast Engine'!O50 | P41: ='Forecast Engine'!P50
B42: Total Current Assets | C42: =SUM(C38:C41) | D42: =SUM(D38:D41) | E42: =SUM(E38:E41) | F42: =SUM(F38:F41) | G42: =SUM(G38:G41) | H42: =SUM(H38:H41) | I42: =SUM(I38:I41) | J42: =J38+J39+J40+J41 | K42: =K38+K39+K40+K41 | L42: =L38+L39+L40+L41 | M42: =M38+M39+M40+M41 | N42: =N38+N39+N40+N41 | O42: =O38+O39+O40+O41 | P42: =P38+P39+P40+P41 | Q42: =SUM(Q38:Q41)
B44: Total Assets | C44: =C42+C35 | D44: =D42+D35 | E44: =E42+E35 | F44: =F42+F35 | G44: =G42+G35 | H44: =H42+H35 | I44: =I42+I35 | J44: =J35+J42 | K44: =K35+K42 | L44: =L35+L42 | M44: =M35+M42 | N44: =N35+N42 | O44: =O35+O42 | P44: =P35+P42 | Q44: =Q42+Q35
B47: Balance check (TA - TE&L) | J47: =J44-J25 | K47: =K44-K25 | L47: =L44-L25 | M47: =M44-M25 | N47: =N44-N25 | O47: =O44-O25 | P47: =P44-P25

Sheet Discrepancies
B1: DATA DISCREPANCIES (BS sheet vs Data Sheet/Screener vs Moneycontrol)
B3: Item | C3: FY20 | D3: FY21 | E3: FY22 | F3: FY23 | G3: FY24 | H3: FY25 | I3: FY26 | J3: Comment
B4: BS-sheet total | C4: 59757.6 | D4: 55251.9 | E4: 56243.8 | F4: 56920 | G4: 59005.5 | H4: 68083.2 | I4: 76185.6 | K4: Sum of your Moneycontrol BS line items.
B5: Data Sheet total (Screener) | C5: 60291 | D5: 55959.7 | E5: 56990.8 | F5: 57663.8 | G5: 59784.1 | H5: 68848.9 | I5: 76185.6 | K5: Screener aggregated total.
B6: Difference | C6: 533.4 | D6: 707.8 | E6: 747 | F6: 743.8 | G6: 778.6 | H6: 765.7 | I6: 0 | K6: FY20-25 gap ~Rs530-780 cr; FY26 reconciles.
B7: Inventory (BS sheet) | C7: 8908.2 | D7: 7194.4 | E7: 6560.2 | F7: 6755.9 | G7: 7220.6 | H7: 9869.5 | I7: 13334.6 | K7: Moneycontrol inventory.
B8: Inventory (Screener) | C8: 9450.7 | D8: 7914 | E8: 7307.3 | F8: 7499.7 | G8: 8002.7 | H8: 10635.3 | I8: 13334.6 | K8: Screener inventory.
B9: Inventory difference | C9: 542.5 | D9: 719.6 | E9: 747.1 | F9: 743.8 | G9: 782.1 | H9: 765.8 | I9: 0 | K9: ROOT CAUSE: equals the total gap. Screener likely includes stores/spares Moneycontrol nets elsewhere.
B10: Borrowings (BS LT+ST) | C10: 4947.9 | D10: 4849.3 | E10: 4745 | F10: 5385 | G10: 8808 | H10: 8795 | I10: 8187 | K10: Moneycontrol.
B11: Borrowings (Screener) | C11: 5080 | D11: 4950.9 | E11: 4829.9 | F11: 5453.5 | G11: 8856.5 | H11: 9014.6 | I11: 8186.9 | K11: Screener; Rs50-220 cr higher FY20-25; FY26 matches.
B13: Other findings
B14: PL 'Selling and admin' is a residual (Gross - Employee - EBITDA): turns POSITIVE in FY22 (+510.6) & FY23 (+351.1) as it absorbs Screener's volatile 'Other Expenses'. EBITDA/EBIT/PBT/PAT are unaffected and correct.
B15: FY23 Cash differs by Rs55 cr (BS 6,642.6 vs Data Sheet 6,698.1).
B16: FY26 cash Rs11,866.6 cr vs debt Rs8,187 cr => BHEL is NET CASH ~Rs3,680 cr (used in forecast).
B17: RESOLUTION: forecast built on your BS-sheet (Moneycontrol) line items - internally balanced and reconciling to Screener in FY26 (the seed year).
